[2024-04-03T23:58:09.287+0000] {scheduler_job_runner.py:781} ERROR - Executor reports task instance <TaskInstance: second_practice_dag.startup scheduled__2024-04-02T00:00:00+00:00 [queued]> finished (failed) although the task says it's queued. (Info: None) Was the task killed externally?
