[2024-04-02T00:12:00.939+0000] {logging_mixin.py:188} INFO - Changing /opt/***/logs/dag_id=dag_python_operator_v4/run_id=scheduled__2024-04-01T00:00:00+00:00/task_id=task1 permission to 509
[2024-04-02T00:12:00.941+0000] {logging_mixin.py:188} INFO - Changing /opt/***/logs/dag_id=dag_python_operator_v4/run_id=scheduled__2024-04-01T00:00:00+00:00 permission to 509
[2024-04-02T00:12:00.942+0000] {logging_mixin.py:188} INFO - Changing /opt/***/logs/dag_id=dag_python_operator_v4 permission to 509
[2024-04-02T00:12:00.944+0000] {logging_mixin.py:188} INFO - Changing /opt/***/logs permission to 509
[2024-04-02T00:12:00.988+0000] {logging_mixin.py:188} INFO - Changing /opt/***/logs/dag_id=dag_python_operator_v4/run_id=scheduled__2024-04-01T00:00:00+00:00/task_id=task1 permission to 509
[2024-04-02T00:12:00.990+0000] {logging_mixin.py:188} INFO - Changing /opt/***/logs/dag_id=dag_python_operator_v4/run_id=scheduled__2024-04-01T00:00:00+00:00 permission to 509
[2024-04-02T00:12:00.992+0000] {logging_mixin.py:188} INFO - Changing /opt/***/logs/dag_id=dag_python_operator_v4 permission to 509
[2024-04-02T00:12:00.994+0000] {logging_mixin.py:188} INFO - Changing /opt/***/logs permission to 509
[2024-04-02T00:12:01.040+0000] {taskinstance.py:1979} INFO - Dependencies all met for dep_context=non-requeueable deps ti=<TaskInstance: dag_python_operator_v4.task1 scheduled__2024-04-01T00:00:00+00:00 [queued]>
[2024-04-02T00:12:01.051+0000] {taskinstance.py:1979} INFO - Dependencies all met for dep_context=requeueable deps ti=<TaskInstance: dag_python_operator_v4.task1 scheduled__2024-04-01T00:00:00+00:00 [queued]>
[2024-04-02T00:12:01.052+0000] {taskinstance.py:2193} INFO - Starting attempt 1 of 6
[2024-04-02T00:12:01.068+0000] {taskinstance.py:2217} INFO - Executing <Task(PythonOperator): task1> on 2024-04-01 00:00:00+00:00
[2024-04-02T00:12:01.072+0000] {standard_task_runner.py:60} INFO - Started process 1929 to run task
[2024-04-02T00:12:01.077+0000] {standard_task_runner.py:87} INFO - Running: ['***', 'tasks', 'run', 'dag_python_operator_v4', 'task1', 'scheduled__2024-04-01T00:00:00+00:00', '--job-id', '137', '--raw', '--subdir', 'DAGS_FOLDER/create_dag_with_python_operator.py', '--cfg-path', '/tmp/tmpym9jy282']
[2024-04-02T00:12:01.079+0000] {standard_task_runner.py:88} INFO - Job 137: Subtask task1
[2024-04-02T00:12:01.135+0000] {logging_mixin.py:188} INFO - Changing /opt/***/logs/dag_id=dag_python_operator_v4/run_id=scheduled__2024-04-01T00:00:00+00:00/task_id=task1 permission to 509
[2024-04-02T00:12:01.137+0000] {logging_mixin.py:188} INFO - Changing /opt/***/logs/dag_id=dag_python_operator_v4/run_id=scheduled__2024-04-01T00:00:00+00:00 permission to 509
[2024-04-02T00:12:01.139+0000] {logging_mixin.py:188} INFO - Changing /opt/***/logs/dag_id=dag_python_operator_v4 permission to 509
[2024-04-02T00:12:01.140+0000] {logging_mixin.py:188} INFO - Changing /opt/***/logs permission to 509
[2024-04-02T00:12:01.143+0000] {task_command.py:423} INFO - Running <TaskInstance: dag_python_operator_v4.task1 scheduled__2024-04-01T00:00:00+00:00 [running]> on host 46dc445f2ec8
[2024-04-02T00:12:01.232+0000] {taskinstance.py:2513} INFO - Exporting env vars: AIRFLOW_CTX_DAG_OWNER='coder2j' AIRFLOW_CTX_DAG_ID='dag_python_operator_v4' AIRFLOW_CTX_TASK_ID='task1' AIRFLOW_CTX_EXECUTION_DATE='2024-04-01T00:00:00+00:00' AIRFLOW_CTX_TRY_NUMBER='1' AIRFLOW_CTX_DAG_RUN_ID='scheduled__2024-04-01T00:00:00+00:00'
[2024-04-02T00:12:01.233+0000] {taskinstance.py:2731} ERROR - Task failed with exception
Traceback (most recent call last):
  File "/home/airflow/.local/lib/python3.8/site-packages/airflow/models/taskinstance.py", line 444, in _execute_task
    result = _execute_callable(context=context, **execute_callable_kwargs)
  File "/home/airflow/.local/lib/python3.8/site-packages/airflow/models/taskinstance.py", line 414, in _execute_callable
    return execute_callable(context=context, **execute_callable_kwargs)
  File "/home/airflow/.local/lib/python3.8/site-packages/airflow/operators/python.py", line 200, in execute
    return_value = self.execute_callable()
  File "/home/airflow/.local/lib/python3.8/site-packages/airflow/operators/python.py", line 217, in execute_callable
    return self.python_callable(*self.op_args, **self.op_kwargs)
  File "/opt/airflow/dags/create_dag_with_python_operator.py", line 16, in greet
    print(f"Hello, World! My name is {ti.xcoms_pull(task_ids = 'task2')}, and I am {age} years old.")
AttributeError: 'TaskInstance' object has no attribute 'xcoms_pull'
[2024-04-02T00:12:01.244+0000] {taskinstance.py:1149} INFO - Marking task as UP_FOR_RETRY. dag_id=dag_python_operator_v4, task_id=task1, execution_date=20240401T000000, start_date=20240402T001201, end_date=20240402T001201
[2024-04-02T00:12:01.260+0000] {standard_task_runner.py:107} ERROR - Failed to execute job 137 for task task1 ('TaskInstance' object has no attribute 'xcoms_pull'; 1929)
[2024-04-02T00:12:01.290+0000] {local_task_job_runner.py:234} INFO - Task exited with return code 1
[2024-04-02T00:12:01.308+0000] {taskinstance.py:3312} INFO - 0 downstream tasks scheduled from follow-on schedule check
